Workbook

Sheet 2024 Summary
A1: Month | B1: Total Invested | C1: Number of Companies | D1: Asset Manager | G1: Blacklist
D2: Danske Bank | E2: Jyske Bank | F2: SEB | G2: UN | H2: AFSC | I2: WhoProfits
A3: 45292 | B3: =Jan!N13 -> 0 | C3: =COUNTIF(Jan!G2:G150,"*") -> 0 | D3: =Jan!O8 -> 0 | E3: =Jan!O9 -> 0 | F3: =Jan!O10 -> 0 | G3: =Jan!O3 -> 0 | H3: =Jan!O4 -> 0 | I3: =Jan!O5 -> 0 | AA3: =Jan!G2 -> 0
A4: =A3+31 -> 45323 | B4: =Feb!N13 -> 0 | C4: =COUNTIF(Feb!G2:G150,"*") -> 0 | D4: =Feb!O8 -> 0 | E4: =Feb!O9 -> 0 | F4: =Feb!O10 -> 0 | G4: =Feb!O3 -> 0 | H4: =Feb!O4 -> 0 | I4: =Feb!O5 -> 0 | AA4: =Jan!G3 -> 0
A5: =A4+31 -> 45354 | B5: =Mar!N13 -> 0 | C5: =COUNTIF(Mar!G2:G150,"*") -> 0 | D5: =Mar!O8 -> 0 | E5: =Mar!O9 -> 0 | F5: =Mar!O10 -> 0 | G5: =Mar!O3 -> 0 | H5: =Mar!O4 -> 0 | I5: =Mar!O5 -> 0 | AA5: =Jan!G4 -> 0
A6: =A5+31 -> 45385 | B6: =Apr!N13 -> 0 | C6: =COUNTIF(Apr!G2:G150,"*") -> 0 | D6: =Apr!O8 -> 0 | E6: =Apr!O9 -> 0 | F6: =Apr!O10 -> 0 | G6: =Apr!O3 -> 0 | H6: =Apr!O4 -> 0 | I6: =Apr!O5 -> 0 | AA6: =Jan!G5 -> 0
A7: =A6+31 -> 45416 | B7: =May!N13 -> 0 | C7: =COUNTIF(May!G2:G150,"*") -> 0 | D7: =May!O8 -> 0 | E7: =May!O9 -> 0 | F7: =May!O10 -> 0 | G7: =May!O3 -> 0 | H7: =May!O4 -> 0 | I7: =May!O5 -> 0 | AA7: =Jan!G6 -> 0
A8: =A7+31 -> 45447 | B8: =Jun!N13 -> 0 | C8: =COUNTIF(Jun!G2:G150,"*") -> 0 | D8: =Jun!O8 -> 0 | E8: =Jun!O9 -> 0 | F8: =Jun!O10 -> 0 | G8: =Jun!O3 -> 0 | H8: =Jun!O4 -> 0 | I8: =Jun!O5 -> 0 | AA8: =Jan!G7 -> 0
A9: =A8+31 -> 45478 | B9: =Jul!N13 -> 0 | C9: =COUNTIF(Jul!G2:G150,"*") -> 0 | D9: =Jul!O8 -> 0 | E9: =Jul!O9 -> 0 | F9: =Jul!O10 -> 0 | G9: =Jul!O3 -> 0 | H9: =Jul!O4 -> 0 | I9: =Jul!O5 -> 0 | AA9: =Jan!G8 -> 0
A10: =A9+31 -> 45509 | B10: =Aug!N13 -> 0 | C10: =COUNTIF(Aug!G2:G150,"*") -> 0 | D10: =Aug!O8 -> 0 | E10: =Aug!O9 -> 0 | F10: =Aug!O10 -> 0 | G10: =Aug!O3 -> 0 | H10: =Aug!O4 -> 0 | I10: =Aug!O5 -> 0 | AA10: =Jan!G9 -> 0
A11: =A10+31 -> 45540 | B11: =Sep!N13 -> 0 | C11: =COUNTIF(Sep!G2:G150,"*") -> 0 | D11: =Sep!O8 -> 0 | E11: =Sep!O9 -> 0 | F11: =Sep!O10 -> 0 | G11: =Sep!O3 -> 0 | H11: =Sep!O4 -> 0 | I11: =Sep!O5 -> 0 | AA11: =Jan!G10 -> 0
A12: =A11+31 -> 45571 | B12: =Oct!N13 -> 0 | C12: =COUNTIF(Oct!G2:G150,"*") -> 0 | D12: =Oct!O8 -> 0 | E12: =Oct!O9 -> 0 | F12: =Oct!O10 -> 0 | G12: =Oct!O3 -> 0 | H12: =Oct!O4 -> 0 | I12: =Oct!O5 -> 0 | AA12: =Jan!G11 -> 0
A13: =A12+31 -> 45602 | B13: =Nov!N13 -> 0 | C13: =COUNTIF(Nov!G2:G150,"*") -> 0 | D13: =Nov!O8 -> 0 | E13: =Nov!O9 -> 0 | F13: =Nov!O10 -> 0 | G13: =Nov!O3 -> 0 | H13: =Nov!O4 -> 0 | I13: =Nov!O5 -> 0 | AA13: =Jan!G12 -> 0
A14: =A13+31 -> 45633 | B14: =Dec!N13 -> 0 | C14: =COUNTIF(Dec!G2:G150,"*") -> 0 | D14: =Dec!O8 -> 0 | E14: =Dec!O9 -> 0 | F14: =Dec!O10 -> 0 | G14: =Dec!O3 -> 0 | H14: =Dec!O4 -> 0 | I14: =Dec!O5 -> 0 | AA14: =Jan!G13 -> 0
A15: Average | B15: =SUM(B3:B14)/COUNTIF(B3:B14,">0") -> #DIV/0! | AA15: =Jan!G14 -> 0
A16: Companies | B16: =COUNTIF(A18:A1000,"*") -> 0 | AA16: =Jan!G15 -> 0
AA17: =Jan!G16 -> 0
A18: {=_xlfn._xlws.SORT(_xlfn.UNIQUE(AA:AA))} -> 0 | B18: =A3 -> 45292 | C18: =A4 -> 45323 | D18: =A5 -> 45354 | E18: =A6 -> 45385 | F18: =A7 -> 45416 | G18: =A8 -> 45447 | H18: =A9 -> 45478 | I18: =A10 -> 45509 | J18: =A11 -> 45540 | K18: =A12 -> 45571 | L18: =A13 -> 45602 | M18: =A14 -> 45633 | AA18: =Jan!G17 -> 0
A19: 0 | B19: =SUMIF(Jan!$G$2:$G$1000,'2024 Summary'!A19,Jan!$H$2:$H$1000) -> 0 | C19: =SUMIF(Feb!$G$2:$G$1000,'2024 Summary'!A19,Feb!$H$2:$H$1000) -> 0 | D19: =SUMIF(Mar!$G$2:$G$1000,'2024 Summary'!A19,Mar!$H$2:$H$1000) -> 0 | E19: =SUMIF(Apr!$G$2:$G$1000,'2024 Summary'!A19,Apr!$H$2:$H$1000) -> 0 | F19: =SUMIF(May!$G$2:$G$1000,'2024 Summary'!A19,May!$H$2:$H$1000) -> 0 | G19: =SUMIF(Jun!$G$2:$G$1000,'2024 Summary'!A19,Jun!$H$2:$H$1000) -> 0 | H19: =SUMIF(Jul!$G$2:$G$1000,'2024 Summary'!A19,Jul!$H$2:$H$1000) -> 0 | I19: =SUMIF(Aug!$G$2:$G$1000,'2024 Summary'!A19,Aug!$H$2:$H$1000) -> 0 | J19: =SUMIF(Sep!$G$2:$G$1000,'2024 Summary'!A19,Sep!$H$2:$H$1000) -> 0 | K19: =SUMIF(Oct!$G$2:$G$1000,'2024 Summary'!A19,Oct!$H$2:$H$1000) -> 0 | L19: =SUMIF(Nov!$G$2:$G$1000,'2024 Summary'!A19,Nov!$H$2:$H$1000) -> 0 | M19: =SUMIF(Dec!$G$2:$G$1000,'2024 Summary'!A19,Dec!$H$2:$H$1000) -> 0 | AA19: =Jan!G18 -> 0
B20: =SUMIF(Jan!$G$2:$G$1000,'2024 Summary'!A20,Jan!$H$2:$H$1000) -> 0 | C20: =SUMIF(Feb!$G$2:$G$1000,'2024 Summary'!A20,Feb!$H$2:$H$1000) -> 0 | D20: =SUMIF(Mar!$G$2:$G$1000,'2024 Summary'!A20,Mar!$H$2:$H$1000) -> 0 | E20: =SUMIF(Apr!$G$2:$G$1000,'2024 Summary'!A20,Apr!$H$2:$H$1000) -> 0 | F20: =SUMIF(May!$G$2:$G$1000,'2024 Summary'!A20,May!$H$2:$H$1000) -> 0 | G20: =SUMIF(Jun!$G$2:$G$1000,'2024 Summary'!A20,Jun!$H$2:$H$1000) -> 0 | H20: =SUMIF(Jul!$G$2:$G$1000,'2024 Summary'!A20,Jul!$H$2:$H$1000) -> 0 | I20: =SUMIF(Aug!$G$2:$G$1000,'2024 Summary'!A20,Aug!$H$2:$H$1000) -> 0 | J20: =SUMIF(Sep!$G$2:$G$1000,'2024 Summary'!A20,Sep!$H$2:$H$1000) -> 0 | K20: =SUMIF(Oct!$G$2:$G$1000,'2024 Summary'!A20,Oct!$H$2:$H$1000) -> 0 | L20: =SUMIF(Nov!$G$2:$G$1000,'2024 Summary'!A20,Nov!$H$2:$H$1000) -> 0 | M20: =SUMIF(Dec!$G$2:$G$1000,'2024 Summary'!A20,Dec!$H$2:$H$1000) -> 0 | AA20: =Jan!G19 -> 0
B21: =SUMIF(Jan!$G$2:$G$1000,'2024 Summary'!A21,Jan!$H$2:$H$1000) -> 0 | C21: =SUMIF(Feb!$G$2:$G$1000,'2024 Summary'!A21,Feb!$H$2:$H$1000) -> 0 | D21: =SUMIF(Mar!$G$2:$G$1000,'2024 Summary'!A21,Mar!$H$2:$H$1000) -> 0 | E21: =SUMIF(Apr!$G$2:$G$1000,'2024 Summary'!A21,Apr!$H$2:$H$1000) -> 0 | F21: =SUMIF(May!$G$2:$G$1000,'2024 Summary'!A21,May!$H$2:$H$1000) -> 0 | G21: =SUMIF(Jun!$G$2:$G$1000,'2024 Summary'!A21,Jun!$H$2:$H$1000) -> 0 | H21: =SUMIF(Jul!$G$2:$G$1000,'2024 Summary'!A21,Jul!$H$2:$H$1000) -> 0 | I21: =SUMIF(Aug!$G$2:$G$1000,'2024 Summary'!A21,Aug!$H$2:$H$1000) -> 0 | J21: =SUMIF(Sep!$G$2:$G$1000,'2024 Summary'!A21,Sep!$H$2:$H$1000) -> 0 | K21: =SUMIF(Oct!$G$2:$G$1000,'2024 Summary'!A21,Oct!$H$2:$H$1000) -> 0 | L21: =SUMIF(Nov!$G$2:$G$1000,'2024 Summary'!A21,Nov!$H$2:$H$1000) -> 0 | M21: =SUMIF(Dec!$G$2:$G$1000,'2024 Summary'!A21,Dec!$H$2:$H$1000) -> 0 | AA21: =Jan!G20 -> 0
B22: =SUMIF(Jan!$G$2:$G$1000,'2024 Summary'!A22,Jan!$H$2:$H$1000) -> 0 | C22: =SUMIF(Feb!$G$2:$G$1000,'2024 Summary'!A22,Feb!$H$2:$H$1000) -> 0 | D22: =SUMIF(Mar!$G$2:$G$1000,'2024 Summary'!A22,Mar!$H$2:$H$1000) -> 0 | E22: =SUMIF(Apr!$G$2:$G$1000,'2024 Summary'!A22,Apr!$H$2:$H$1000) -> 0 | F22: =SUMIF(May!$G$2:$G$1000,'2024 Summary'!A22,May!$H$2:$H$1000) -> 0 | G22: =SUMIF(Jun!$G$2:$G$1000,'2024 Summary'!A22,Jun!$H$2:$H$1000) -> 0 | H22: =SUMIF(Jul!$G$2:$G$1000,'2024 Summary'!A22,Jul!$H$2:$H$1000) -> 0 | I22: =SUMIF(Aug!$G$2:$G$1000,'2024 Summary'!A22,Aug!$H$2:$H$1000) -> 0 | J22: =SUMIF(Sep!$G$2:$G$1000,'2024 Summary'!A22,Sep!$H$2:$H$1000) -> 0 | K22: =SUMIF(Oct!$G$2:$G$1000,'2024 Summary'!A22,Oct!$H$2:$H$1000) -> 0 | L22: =SUMIF(Nov!$G$2:$G$1000,'2024 Summary'!A22,Nov!$H$2:$H$1000) -> 0 | M22: =SUMIF(Dec!$G$2:$G$1000,'2024 Summary'!A22,Dec!$H$2:$H$1000) -> 0 | AA22: =Jan!G21 -> 0
B23: =SUMIF(Jan!$G$2:$G$1000,'2024 Summary'!A23,Jan!$H$2:$H$1000) -> 0 | C23: =SUMIF(Feb!$G$2:$G$1000,'2024 Summary'!A23,Feb!$H$2:$H$1000) -> 0 | D23: =SUMIF(Mar!$G$2:$G$1000,'2024 Summary'!A23,Mar!$H$2:$H$1000) -> 0 | E23: =SUMIF(Apr!$G$2:$G$1000,'2024 Summary'!A23,Apr!$H$2:$H$1000) -> 0 | F23: =SUMIF(May!$G$2:$G$1000,'2024 Summary'!A23,May!$H$2:$H$1000) -> 0 | G23: =SUMIF(Jun!$G$2:$G$1000,'2024 Summary'!A23,Jun!$H$2:$H$1000) -> 0 | H23: =SUMIF(Jul!$G$2:$G$1000,'2024 Summary'!A23,Jul!$H$2:$H$1000) -> 0 | I23: =SUMIF(Aug!$G$2:$G$1000,'2024 Summary'!A23,Aug!$H$2:$H$1000) -> 0 | J23: =SUMIF(Sep!$G$2:$G$1000,'2024 Summary'!A23,Sep!$H$2:$H$1000) -> 0 | K23: =SUMIF(Oct!$G$2:$G$1000,'2024 Summary'!A23,Oct!$H$2:$H$1000) -> 0 | L23: =SUMIF(Nov!$G$2:$G$1000,'2024 Summary'!A23,Nov!$H$2:$H$1000) -> 0 | M23: =SUMIF(Dec!$G$2:$G$1000,'2024 Summary'!A23,Dec!$H$2:$H$1000) -> 0 | AA23: =Jan!G22 -> 0
B24: =SUMIF(Jan!$G$2:$G$1000,'2024 Summary'!A24,Jan!$H$2:$H$1000) -> 0 | C24: =SUMIF(Feb!$G$2:$G$1000,'2024 Summary'!A24,Feb!$H$2:$H$1000) -> 0 | D24: =SUMIF(Mar!$G$2:$G$1000,'2024 Summary'!A24,Mar!$H$2:$H$1000) -> 0 | E24: =SUMIF(Apr!$G$2:$G$1000,'2024 Summary'!A24,Apr!$H$2:$H$1000) -> 0 | F24: =SUMIF(May!$G$2:$G$1000,'2024 Summary'!A24,May!$H$2:$H$1000) -> 0 | G24: =SUMIF(Jun!$G$2:$G$1000,'2024 Summary'!A24,Jun!$H$2:$H$1000) -> 0 | H24: =SUMIF(Jul!$G$2:$G$1000,'2024 Summary'!A24,Jul!$H$2:$H$1000) -> 0 | I24: =SUMIF(Aug!$G$2:$G$1000,'2024 Summary'!A24,Aug!$H$2:$H$1000) -> 0 | J24: =SUMIF(Sep!$G$2:$G$1000,'2024 Summary'!A24,Sep!$H$2:$H$1000) -> 0 | K24: =SUMIF(Oct!$G$2:$G$1000,'2024 Summary'!A24,Oct!$H$2:$H$1000) -> 0 | L24: =SUMIF(Nov!$G$2:$G$1000,'2024 Summary'!A24,Nov!$H$2:$H$1000) -> 0 | M24: =SUMIF(Dec!$G$2:$G$1000,'2024 Summary'!A24,Dec!$H$2:$H$1000) -> 0 | AA24: =Jan!G23 -> 0
B25: =SUMIF(Jan!$G$2:$G$1000,'2024 Summary'!A25,Jan!$H$2:$H$1000) -> 0 | C25: =SUMIF(Feb!$G$2:$G$1000,'2024 Summary'!A25,Feb!$H$2:$H$1000) -> 0 | D25: =SUMIF(Mar!$G$2:$G$1000,'2024 Summary'!A25,Mar!$H$2:$H$1000) -> 0 | E25: =SUMIF(Apr!$G$2:$G$1000,'2024 Summary'!A25,Apr!$H$2:$H$1000) -> 0 | F25: =SUMIF(May!$G$2:$G$1000,'2024 Summary'!A25,May!$H$2:$H$1000) -> 0 | G25: =SUMIF(Jun!$G$2:$G$1000,'2024 Summary'!A25,Jun!$H$2:$H$1000) -> 0 | H25: =SUMIF(Jul!$G$2:$G$1000,'2024 Summary'!A25,Jul!$H$2:$H$1000) -> 0 | I25: =SUMIF(Aug!$G$2:$G$1000,'2024 Summary'!A25,Aug!$H$2:$H$1000) -> 0 | J25: =SUMIF(Sep!$G$2:$G$1000,'2024 Summary'!A25,Sep!$H$2:$H$1000) -> 0 | K25: =SUMIF(Oct!$G$2:$G$1000,'2024 Summary'!A25,Oct!$H$2:$H$1000) -> 0 | L25: =SUMIF(Nov!$G$2:$G$1000,'2024 Summary'!A25,Nov!$H$2:$H$1000) -> 0 | M25: =SUMIF(Dec!$G$2:$G$1000,'2024 Summary'!A25,Dec!$H$2:$H$1000) -> 0 | AA25: =Jan!G24 -> 0
B26: =SUMIF(Jan!$G$2:$G$1000,'2024 Summary'!A26,Jan!$H$2:$H$1000) -> 0 | C26: =SUMIF(Feb!$G$2:$G$1000,'2024 Summary'!A26,Feb!$H$2:$H$1000) -> 0 | D26: =SUMIF(Mar!$G$2:$G$1000,'2024 Summary'!A26,Mar!$H$2:$H$1000) -> 0 | E26: =SUMIF(Apr!$G$2:$G$1000,'2024 Summary'!A26,Apr!$H$2:$H$1000) -> 0 | F26: =SUMIF(May!$G$2:$G$1000,'2024 Summary'!A26,May!$H$2:$H$1000) -> 0 | G26: =SUMIF(Jun!$G$2:$G$1000,'2024 Summary'!A26,Jun!$H$2:$H$1000) -> 0 | H26: =SUMIF(Jul!$G$2:$G$1000,'2024 Summary'!A26,Jul!$H$2:$H$1000) -> 0 | I26: =SUMIF(Aug!$G$2:$G$1000,'2024 Summary'!A26,Aug!$H$2:$H$1000) -> 0 | J26: =SUMIF(Sep!$G$2:$G$1000,'2024 Summary'!A26,Sep!$H$2:$H$1000) -> 0 | K26: =SUMIF(Oct!$G$2:$G$1000,'2024 Summary'!A26,Oct!$H$2:$H$1000) -> 0 | L26: =SUMIF(Nov!$G$2:$G$1000,'2024 Summary'!A26,Nov!$H$2:$H$1000) -> 0 | M26: =SUMIF(Dec!$G$2:$G$1000,'2024 Summary'!A26,Dec!$H$2:$H$1000) -> 0 | AA26: =Jan!G25 -> 0
B27: =SUMIF(Jan!$G$2:$G$1000,'2024 Summary'!A27,Jan!$H$2:$H$1000) -> 0 | C27: =SUMIF(Feb!$G$2:$G$1000,'2024 Summary'!A27,Feb!$H$2:$H$1000) -> 0 | D27: =SUMIF(Mar!$G$2:$G$1000,'2024 Summary'!A27,Mar!$H$2:$H$1000) -> 0 | E27: =SUMIF(Apr!$G$2:$G$1000,'2024 Summary'!A27,Apr!$H$2:$H$1000) -> 0 | F27: =SUMIF(May!$G$2:$G$1000,'2024 Summary'!A27,May!$H$2:$H$1000) -> 0 | G27: =SUMIF(Jun!$G$2:$G$1000,'2024 Summary'!A27,Jun!$H$2:$H$1000) -> 0 | H27: =SUMIF(Jul!$G$2:$G$1000,'2024 Summary'!A27,Jul!$H$2:$H$1000) -> 0 | I27: =SUMIF(Aug!$G$2:$G$1000,'2024 Summary'!A27,Aug!$H$2:$H$1000) -> 0 | J27: =SUMIF(Sep!$G$2:$G$1000,'2024 Summary'!A27,Sep!$H$2:$H$1000) -> 0 | K27: =SUMIF(Oct!$G$2:$G$1000,'2024 Summary'!A27,Oct!$H$2:$H$1000) -> 0 | L27: =SUMIF(Nov!$G$2:$G$1000,'2024 Summary'!A27,Nov!$H$2:$H$1000) -> 0 | M27: =SUMIF(Dec!$G$2:$G$1000,'2024 Summary'!A27,Dec!$H$2:$H$1000) -> 0 | AA27: =Jan!G26 -> 0
B28: =SUMIF(Jan!$G$2:$G$1000,'2024 Summary'!A28,Jan!$H$2:$H$1000) -> 0 | C28: =SUMIF(Feb!$G$2:$G$1000,'2024 Summary'!A28,Feb!$H$2:$H$1000) -> 0 | D28: =SUMIF(Mar!$G$2:$G$1000,'2024 Summary'!A28,Mar!$H$2:$H$1000) -> 0 | E28: =SUMIF(Apr!$G$2:$G$1000,'2024 Summary'!A28,Apr!$H$2:$H$1000) -> 0 | F28: =SUMIF(May!$G$2:$G$1000,'2024 Summary'!A28,May!$H$2:$H$1000) -> 0 | G28: =SUMIF(Jun!$G$2:$G$1000,'2024 Summary'!A28,Jun!$H$2:$H$1000) -> 0 | H28: =SUMIF(Jul!$G$2:$G$1000,'2024 Summary'!A28,Jul!$H$2:$H$1000) -> 0 | I28: =SUMIF(Aug!$G$2:$G$1000,'2024 Summary'!A28,Aug!$H$2:$H$1000) -> 0 | J28: =SUMIF(Sep!$G$2:$G$1000,'2024 Summary'!A28,Sep!$H$2:$H$1000) -> 0 | K28: =SUMIF(Oct!$G$2:$G$1000,'2024 Summary'!A28,Oct!$H$2:$H$1000) -> 0 | L28: =SUMIF(Nov!$G$2:$G$1000,'2024 Summary'!A28,Nov!$H$2:$H$1000) -> 0 | M28: =SUMIF(Dec!$G$2:$G$1000,'2024 Summary'!A28,Dec!$H$2:$H$1000) -> 0 | AA28: =Jan!G27 -> 0
B29: =SUMIF(Jan!$G$2:$G$1000,'2024 Summary'!A29,Jan!$H$2:$H$1000) -> 0 | C29: =SUMIF(Feb!$G$2:$G$1000,'2024 Summary'!A29,Feb!$H$2:$H$1000) -> 0 | D29: =SUMIF(Mar!$G$2:$G$1000,'2024 Summary'!A29,Mar!$H$2:$H$1000) -> 0 | E29: =SUMIF(Apr!$G$2:$G$1000,'2024 Summary'!A29,Apr!$H$2:$H$1000) -> 0 | F29: =SUMIF(May!$G$2:$G$1000,'2024 Summary'!A29,May!$H$2:$H$1000) -> 0 | G29: =SUMIF(Jun!$G$2:$G$1000,'2024 Summary'!A29,Jun!$H$2:$H$1000) -> 0 | H29: =SUMIF(Jul!$G$2:$G$1000,'2024 Summary'!A29,Jul!$H$2:$H$1000) -> 0 | I29: =SUMIF(Aug!$G$2:$G$1000,'2024 Summary'!A29,Aug!$H$2:$H$1000) -> 0 | J29: =SUMIF(Sep!$G$2:$G$1000,'2024 Summary'!A29,Sep!$H$2:$H$1000) -> 0 | K29: =SUMIF(Oct!$G$2:$G$1000,'2024 Summary'!A29,Oct!$H$2:$H$1000) -> 0 | L29: =SUMIF(Nov!$G$2:$G$1000,'2024 Summary'!A29,Nov!$H$2:$H$1000) -> 0 | M29: =SUMIF(Dec!$G$2:$G$1000,'2024 Summary'!A29,Dec!$H$2:$H$1000) -> 0 | AA29: =Jan!G28 -> 0
B30: =SUMIF(Jan!$G$2:$G$1000,'2024 Summary'!A30,Jan!$H$2:$H$1000) -> 0 | C30: =SUMIF(Feb!$G$2:$G$1000,'2024 Summary'!A30,Feb!$H$2:$H$1000) -> 0 | D30: =SUMIF(Mar!$G$2:$G$1000,'2024 Summary'!A30,Mar!$H$2:$H$1000) -> 0 | E30: =SUMIF(Apr!$G$2:$G$1000,'2024 Summary'!A30,Apr!$H$2:$H$1000) -> 0 | F30: =SUMIF(May!$G$2:$G$1000,'2024 Summary'!A30,May!$H$2:$H$1000) -> 0 | G30: =SUMIF(Jun!$G$2:$G$1000,'2024 Summary'!A30,Jun!$H$2:$H$1000) -> 0 | H30: =SUMIF(Jul!$G$2:$G$1000,'2024 Summary'!A30,Jul!$H$2:$H$1000) -> 0 | I30: =SUMIF(Aug!$G$2:$G$1000,'2024 Summary'!A30,Aug!$H$2:$H$1000) -> 0 | J30: =SUMIF(Sep!$G$2:$G$1000,'2024 Summary'!A30,Sep!$H$2:$H$1000) -> 0 | K30: =SUMIF(Oct!$G$2:$G$1000,'2024 Summary'!A30,Oct!$H$2:$H$1000) -> 0 | L30: =SUMIF(Nov!$G$2:$G$1000,'2024 Summary'!A30,Nov!$H$2:$H$1000) -> 0 | M30: =SUMIF(Dec!$G$2:$G$1000,'2024 Summary'!A30,Dec!$H$2:$H$1000) -> 0 | AA30: =Jan!G29 -> 0
B31: =SUMIF(Jan!$G$2:$G$1000,'2024 Summary'!A31,Jan!$H$2:$H$1000) -> 0 | C31: =SUMIF(Feb!$G$2:$G$1000,'2024 Summary'!A31,Feb!$H$2:$H$1000) -> 0 | D31: =SUMIF(Mar!$G$2:$G$1000,'2024 Summary'!A31,Mar!$H$2:$H$1000) -> 0 | E31: =SUMIF(Apr!$G$2:$G$1000,'2024 Summary'!A31,Apr!$H$2:$H$1000) -> 0 | F31: =SUMIF(May!$G$2:$G$1000,'2024 Summary'!A31,May!$H$2:$H$1000) -> 0 | G31: =SUMIF(Jun!$G$2:$G$1000,'2024 Summary'!A31,Jun!$H$2:$H$1000) -> 0 | H31: =SUMIF(Jul!$G$2:$G$1000,'2024 Summary'!A31,Jul!$H$2:$H$1000) -> 0 | I31: =SUMIF(Aug!$G$2:$G$1000,'2024 Summary'!A31,Aug!$H$2:$H$1000) -> 0 | J31: =SUMIF(Sep!$G$2:$G$1000,'2024 Summary'!A31,Sep!$H$2:$H$1000) -> 0 | K31: =SUMIF(Oct!$G$2:$G$1000,'2024 Summary'!A31,Oct!$H$2:$H$1000) -> 0 | L31: =SUMIF(Nov!$G$2:$G$1000,'2024 Summary'!A31,Nov!$H$2:$H$1000) -> 0 | M31: =SUMIF(Dec!$G$2:$G$1000,'2024 Summary'!A31,Dec!$H$2:$H$1000) -> 0 | AA31: =Jan!G30 -> 0
... B98: =SUMIF(Jan!$G$2:$G$1000,'2024 Summary'!A98,Jan!$H$2:$H$1000) -> 0 | C98: =SUMIF(Feb!$G$2:$G$1000,'2024 Summary'!A98,Feb!$H$2:$H$1000) -> 0 | D98: =SUMIF(Mar!$G$2:$G$1000,'2024 Summary'!A98,Mar!$H$2:$H$1000) -> 0 | E98: =SUMIF(Apr!$G$2:$G$1000,'2024 Summary'!A98,Apr!$H$2:$H$1000) -> 0 | F98: =SUMIF(May!$G$2:$G$1000,'2024 Summary'!A98,May!$H$2:$H$1000) -> 0 | G98: =SUMIF(Jun!$G$2:$G$1000,'2024 Summary'!A98,Jun!$H$2:$H$1000) -> 0 | H98: =SUMIF(Jul!$G$2:$G$1000,'2024 Summary'!A98,Jul!$H$2:$H$1000) -> 0 | I98: =SUMIF(Aug!$G$2:$G$1000,'2024 Summary'!A98,Aug!$H$2:$H$1000) -> 0 | J98: =SUMIF(Sep!$G$2:$G$1000,'2024 Summary'!A98,Sep!$H$2:$H$1000) -> 0 | K98: =SUMIF(Oct!$G$2:$G$1000,'2024 Summary'!A98,Oct!$H$2:$H$1000) -> 0 | L98: =SUMIF(Nov!$G$2:$G$1000,'2024 Summary'!A98,Nov!$H$2:$H$1000) -> 0 | M98: =SUMIF(Dec!$G$2:$G$1000,'2024 Summary'!A98,Dec!$H$2:$H$1000) -> 0 | AA98: =Jan!G97 -> 0
B99: =SUMIF(Jan!$G$2:$G$1000,'2024 Summary'!A99,Jan!$H$2:$H$1000) -> 0 | C99: =SUMIF(Feb!$G$2:$G$1000,'2024 Summary'!A99,Feb!$H$2:$H$1000) -> 0 | D99: =SUMIF(Mar!$G$2:$G$1000,'2024 Summary'!A99,Mar!$H$2:$H$1000) -> 0 | E99: =SUMIF(Apr!$G$2:$G$1000,'2024 Summary'!A99,Apr!$H$2:$H$1000) -> 0 | F99: =SUMIF(May!$G$2:$G$1000,'2024 Summary'!A99,May!$H$2:$H$1000) -> 0 | G99: =SUMIF(Jun!$G$2:$G$1000,'2024 Summary'!A99,Jun!$H$2:$H$1000) -> 0 | H99: =SUMIF(Jul!$G$2:$G$1000,'2024 Summary'!A99,Jul!$H$2:$H$1000) -> 0 | I99: =SUMIF(Aug!$G$2:$G$1000,'2024 Summary'!A99,Aug!$H$2:$H$1000) -> 0 | J99: =SUMIF(Sep!$G$2:$G$1000,'2024 Summary'!A99,Sep!$H$2:$H$1000) -> 0 | K99: =SUMIF(Oct!$G$2:$G$1000,'2024 Summary'!A99,Oct!$H$2:$H$1000) -> 0 | L99: =SUMIF(Nov!$G$2:$G$1000,'2024 Summary'!A99,Nov!$H$2:$H$1000) -> 0 | M99: =SUMIF(Dec!$G$2:$G$1000,'2024 Summary'!A99,Dec!$H$2:$H$1000) -> 0
B100: =SUMIF(Jan!$G$2:$G$1000,'2024 Summary'!A100,Jan!$H$2:$H$1000) -> 0 | C100: =SUMIF(Feb!$G$2:$G$1000,'2024 Summary'!A100,Feb!$H$2:$H$1000) -> 0 | D100: =SUMIF(Mar!$G$2:$G$1000,'2024 Summary'!A100,Mar!$H$2:$H$1000) -> 0 | E100: =SUMIF(Apr!$G$2:$G$1000,'2024 Summary'!A100,Apr!$H$2:$H$1000) -> 0 | F100: =SUMIF(May!$G$2:$G$1000,'2024 Summary'!A100,May!$H$2:$H$1000) -> 0 | G100: =SUMIF(Jun!$G$2:$G$1000,'2024 Summary'!A100,Jun!$H$2:$H$1000) -> 0 | H100: =SUMIF(Jul!$G$2:$G$1000,'2024 Summary'!A100,Jul!$H$2:$H$1000) -> 0 | I100: =SUMIF(Aug!$G$2:$G$1000,'2024 Summary'!A100,Aug!$H$2:$H$1000) -> 0 | J100: =SUMIF(Sep!$G$2:$G$1000,'2024 Summary'!A100,Sep!$H$2:$H$1000) -> 0 | K100: =SUMIF(Oct!$G$2:$G$1000,'2024 Summary'!A100,Oct!$H$2:$H$1000) -> 0 | L100: =SUMIF(Nov!$G$2:$G$1000,'2024 Summary'!A100,Nov!$H$2:$H$1000) -> 0 | M100: =SUMIF(Dec!$G$2:$G$1000,'2024 Summary'!A100,Dec!$H$2:$H$1000) -> 0 | AA100: =Feb!G2 -> 0
B101: =SUMIF(Jan!$G$2:$G$1000,'2024 Summary'!A101,Jan!$H$2:$H$1000) -> 0 | C101: =SUMIF(Feb!$G$2:$G$1000,'2024 Summary'!A101,Feb!$H$2:$H$1000) -> 0 | D101: =SUMIF(Mar!$G$2:$G$1000,'2024 Summary'!A101,Mar!$H$2:$H$1000) -> 0 | E101: =SUMIF(Apr!$G$2:$G$1000,'2024 Summary'!A101,Apr!$H$2:$H$1000) -> 0 | F101: =SUMIF(May!$G$2:$G$1000,'2024 Summary'!A101,May!$H$2:$H$1000) -> 0 | G101: =SUMIF(Jun!$G$2:$G$1000,'2024 Summary'!A101,Jun!$H$2:$H$1000) -> 0 | H101: =SUMIF(Jul!$G$2:$G$1000,'2024 Summary'!A101,Jul!$H$2:$H$1000) -> 0 | I101: =SUMIF(Aug!$G$2:$G$1000,'2024 Summary'!A101,Aug!$H$2:$H$1000) -> 0 | J101: =SUMIF(Sep!$G$2:$G$1000,'2024 Summary'!A101,Sep!$H$2:$H$1000) -> 0 | K101: =SUMIF(Oct!$G$2:$G$1000,'2024 Summary'!A101,Oct!$H$2:$H$1000) -> 0 | L101: =SUMIF(Nov!$G$2:$G$1000,'2024 Summary'!A101,Nov!$H$2:$H$1000) -> 0 | M101: =SUMIF(Dec!$G$2:$G$1000,'2024 Summary'!A101,Dec!$H$2:$H$1000) -> 0 | AA101: =Feb!G3 -> 0
B102: =SUMIF(Jan!$G$2:$G$1000,'2024 Summary'!A102,Jan!$H$2:$H$1000) -> 0 | C102: =SUMIF(Feb!$G$2:$G$1000,'2024 Summary'!A102,Feb!$H$2:$H$1000) -> 0 | D102: =SUMIF(Mar!$G$2:$G$1000,'2024 Summary'!A102,Mar!$H$2:$H$1000) -> 0 | E102: =SUMIF(Apr!$G$2:$G$1000,'2024 Summary'!A102,Apr!$H$2:$H$1000) -> 0 | F102: =SUMIF(May!$G$2:$G$1000,'2024 Summary'!A102,May!$H$2:$H$1000) -> 0 | G102: =SUMIF(Jun!$G$2:$G$1000,'2024 Summary'!A102,Jun!$H$2:$H$1000) -> 0 | H102: =SUMIF(Jul!$G$2:$G$1000,'2024 Summary'!A102,Jul!$H$2:$H$1000) -> 0 | I102: =SUMIF(Aug!$G$2:$G$1000,'2024 Summary'!A102,Aug!$H$2:$H$1000) -> 0 | J102: =SUMIF(Sep!$G$2:$G$1000,'2024 Summary'!A102,Sep!$H$2:$H$1000) -> 0 | K102: =SUMIF(Oct!$G$2:$G$1000,'2024 Summary'!A102,Oct!$H$2:$H$1000) -> 0 | L102: =SUMIF(Nov!$G$2:$G$1000,'2024 Summary'!A102,Nov!$H$2:$H$1000) -> 0 | M102: =SUMIF(Dec!$G$2:$G$1000,'2024 Summary'!A102,Dec!$H$2:$H$1000) -> 0 | AA102: =Feb!G4 -> 0
B103: =SUMIF(Jan!$G$2:$G$1000,'2024 Summary'!A103,Jan!$H$2:$H$1000) -> 0 | C103: =SUMIF(Feb!$G$2:$G$1000,'2024 Summary'!A103,Feb!$H$2:$H$1000) -> 0 | D103: =SUMIF(Mar!$G$2:$G$1000,'2024 Summary'!A103,Mar!$H$2:$H$1000) -> 0 | E103: =SUMIF(Apr!$G$2:$G$1000,'2024 Summary'!A103,Apr!$H$2:$H$1000) -> 0 | F103: =SUMIF(May!$G$2:$G$1000,'2024 Summary'!A103,May!$H$2:$H$1000) -> 0 | G103: =SUMIF(Jun!$G$2:$G$1000,'2024 Summary'!A103,Jun!$H$2:$H$1000) -> 0 | H103: =SUMIF(Jul!$G$2:$G$1000,'2024 Summary'!A103,Jul!$H$2:$H$1000) -> 0 | I103: =SUMIF(Aug!$G$2:$G$1000,'2024 Summary'!A103,Aug!$H$2:$H$1000) -> 0 | J103: =SUMIF(Sep!$G$2:$G$1000,'2024 Summary'!A103,Sep!$H$2:$H$1000) -> 0 | K103: =SUMIF(Oct!$G$2:$G$1000,'2024 Summary'!A103,Oct!$H$2:$H$1000) -> 0 | L103: =SUMIF(Nov!$G$2:$G$1000,'2024 Summary'!A103,Nov!$H$2:$H$1000) -> 0 | M103: =SUMIF(Dec!$G$2:$G$1000,'2024 Summary'!A103,Dec!$H$2:$H$1000) -> 0 | AA103: =Feb!G5 -> 0
B104: =SUMIF(Jan!$G$2:$G$1000,'2024 Summary'!A104,Jan!$H$2:$H$1000) -> 0 | C104: =SUMIF(Feb!$G$2:$G$1000,'2024 Summary'!A104,Feb!$H$2:$H$1000) -> 0 | D104: =SUMIF(Mar!$G$2:$G$1000,'2024 Summary'!A104,Mar!$H$2:$H$1000) -> 0 | E104: =SUMIF(Apr!$G$2:$G$1000,'2024 Summary'!A104,Apr!$H$2:$H$1000) -> 0 | F104: =SUMIF(May!$G$2:$G$1000,'2024 Summary'!A104,May!$H$2:$H$1000) -> 0 | G104: =SUMIF(Jun!$G$2:$G$1000,'2024 Summary'!A104,Jun!$H$2:$H$1000) -> 0 | H104: =SUMIF(Jul!$G$2:$G$1000,'2024 Summary'!A104,Jul!$H$2:$H$1000) -> 0 | I104: =SUMIF(Aug!$G$2:$G$1000,'2024 Summary'!A104,Aug!$H$2:$H$1000) -> 0 | J104: =SUMIF(Sep!$G$2:$G$1000,'2024 Summary'!A104,Sep!$H$2:$H$1000) -> 0 | K104: =SUMIF(Oct!$G$2:$G$1000,'2024 Summary'!A104,Oct!$H$2:$H$1000) -> 0 | L104: =SUMIF(Nov!$G$2:$G$1000,'2024 Summary'!A104,Nov!$H$2:$H$1000) -> 0 | M104: =SUMIF(Dec!$G$2:$G$1000,'2024 Summary'!A104,Dec!$H$2:$H$1000) -> 0 | AA104: =Feb!G6 -> 0
B105: =SUMIF(Jan!$G$2:$G$1000,'2024 Summary'!A105,Jan!$H$2:$H$1000) -> 0 | C105: =SUMIF(Feb!$G$2:$G$1000,'2024 Summary'!A105,Feb!$H$2:$H$1000) -> 0 | D105: =SUMIF(Mar!$G$2:$G$1000,'2024 Summary'!A105,Mar!$H$2:$H$1000) -> 0 | E105: =SUMIF(Apr!$G$2:$G$1000,'2024 Summary'!A105,Apr!$H$2:$H$1000) -> 0 | F105: =SUMIF(May!$G$2:$G$1000,'2024 Summary'!A105,May!$H$2:$H$1000) -> 0 | G105: =SUMIF(Jun!$G$2:$G$1000,'2024 Summary'!A105,Jun!$H$2:$H$1000) -> 0 | H105: =SUMIF(Jul!$G$2:$G$1000,'2024 Summary'!A105,Jul!$H$2:$H$1000) -> 0 | I105: =SUMIF(Aug!$G$2:$G$1000,'2024 Summary'!A105,Aug!$H$2:$H$1000) -> 0 | J105: =SUMIF(Sep!$G$2:$G$1000,'2024 Summary'!A105,Sep!$H$2:$H$1000) -> 0 | K105: =SUMIF(Oct!$G$2:$G$1000,'2024 Summary'!A105,Oct!$H$2:$H$1000) -> 0 | L105: =SUMIF(Nov!$G$2:$G$1000,'2024 Summary'!A105,Nov!$H$2:$H$1000) -> 0 | M105: =SUMIF(Dec!$G$2:$G$1000,'2024 Summary'!A105,Dec!$H$2:$H$1000) -> 0 | AA105: =Feb!G7 -> 0
B106: =SUMIF(Jan!$G$2:$G$1000,'2024 Summary'!A106,Jan!$H$2:$H$1000) -> 0 | C106: =SUMIF(Feb!$G$2:$G$1000,'2024 Summary'!A106,Feb!$H$2:$H$1000) -> 0 | D106: =SUMIF(Mar!$G$2:$G$1000,'2024 Summary'!A106,Mar!$H$2:$H$1000) -> 0 | E106: =SUMIF(Apr!$G$2:$G$1000,'2024 Summary'!A106,Apr!$H$2:$H$1000) -> 0 | F106: =SUMIF(May!$G$2:$G$1000,'2024 Summary'!A106,May!$H$2:$H$1000) -> 0 | G106: =SUMIF(Jun!$G$2:$G$1000,'2024 Summary'!A106,Jun!$H$2:$H$1000) -> 0 | H106: =SUMIF(Jul!$G$2:$G$1000,'2024 Summary'!A106,Jul!$H$2:$H$1000) -> 0 | I106: =SUMIF(Aug!$G$2:$G$1000,'2024 Summary'!A106,Aug!$H$2:$H$1000) -> 0 | J106: =SUMIF(Sep!$G$2:$G$1000,'2024 Summary'!A106,Sep!$H$2:$H$1000) -> 0 | K106: =SUMIF(Oct!$G$2:$G$1000,'2024 Summary'!A106,Oct!$H$2:$H$1000) -> 0 | L106: =SUMIF(Nov!$G$2:$G$1000,'2024 Summary'!A106,Nov!$H$2:$H$1000) -> 0 | M106: =SUMIF(Dec!$G$2:$G$1000,'2024 Summary'!A106,Dec!$H$2:$H$1000) -> 0 | AA106: =Feb!G8 -> 0
...

Sheet Jan
A1: Date | B1: Asset Manager | C1: Investment | D1: Company | E1: Value | G1: Summary | H1: Value | I1: Lists | N1: List | O1: Value
A2: ='2024 Summary'!A3 -> 45292 | G2: {=_xlfn._xlws.SORT(_xlfn.UNIQUE(D2:D1000))} -> 0 | H2: =SUMIF($D$2:$D$1000,G2,$E$2:$E$1000) -> 0 | N2: UN Blacklist 2023 | O2: =SUMIF($I$2:$I$1000,"*UN Blacklist 2023*",$H$2:$H$1000) -> 0
H3: =SUMIF($D$2:$D$1000,G3,$E$2:$E$1000) -> 0 | N3: UN Blacklist 2025 | O3: =SUMIF($I$2:$I$1000,"*UN Blacklist 2025*",$H$2:$H$1000) -> 0
H4: =SUMIF($D$2:$D$1000,G4,$E$2:$E$1000) -> 0 | N4: AFSC Divestment List 2025 | O4: =SUMIF($I$2:$I$971000,"*AFSC Divestment List 2025*",$H$2:$H$1000) -> 0
H5: =SUMIF($D$2:$D$1000,G5,$E$2:$E$1000) -> 0 | N5: WhoProfits | O5: =SUMIF($I$2:$I$1000,"*Who Profits*",$H$2:$H$1000) -> 0
H6: =SUMIF($D$2:$D$1000,G6,$E$2:$E$1000) -> 0
H7: =SUMIF($D$2:$D$1000,G7,$E$2:$E$1000) -> 0 | N7: Bank | O7: Value
H8: =SUMIF($D$2:$D$1000,G8,$E$2:$E$1000) -> 0 | N8: Danske Bank | O8: =SUMIF($B$2:$B$1000,"*Danske Bank*",$E$2:$E$1000) -> 0
H9: =SUMIF($D$2:$D$1000,G9,$E$2:$E$1000) -> 0 | N9: Jyske Bank | O9: =SUMIF($B$2:$B$1000,"*Jyske Bank*",$E$2:$E$1000) -> 0
H10: =SUMIF($D$2:$D$1000,G10,$E$2:$E$1000) -> 0 | N10: SEB | O10: =SUMIF($B$2:$B$1000,"*SEB*",$E$2:$E$1000) -> 0
H11: =SUMIF($D$2:$D$1000,G11,$E$2:$E$1000) -> 0
H12: =SUMIF($D$2:$D$1000,G12,$E$2:$E$1000) -> 0 | N12: Total
H13: =SUMIF($D$2:$D$1000,G13,$E$2:$E$1000) -> 0 | N13: =SUM(E2:E1000) -> 0
H14: =SUMIF($D$2:$D$1000,G14,$E$2:$E$1000) -> 0
H15: =SUMIF($D$2:$D$1000,G15,$E$2:$E$1000) -> 0
H16: =SUMIF($D$2:$D$1000,G16,$E$2:$E$1000) -> 0
H17: =SUMIF($D$2:$D$1000,G17,$E$2:$E$1000) -> 0
H18: =SUMIF($D$2:$D$1000,G18,$E$2:$E$1000) -> 0
H19: =SUMIF($D$2:$D$1000,G19,$E$2:$E$1000) -> 0
H20: =SUMIF($D$2:$D$1000,G20,$E$2:$E$1000) -> 0
H21: =SUMIF($D$2:$D$1000,G21,$E$2:$E$1000) -> 0
H22: =SUMIF($D$2:$D$1000,G22,$E$2:$E$1000) -> 0
H23: =SUMIF($D$2:$D$1000,G23,$E$2:$E$1000) -> 0
H24: =SUMIF($D$2:$D$1000,G24,$E$2:$E$1000) -> 0
H25: =SUMIF($D$2:$D$1000,G25,$E$2:$E$1000) -> 0
... H151: =SUMIF($D$2:$D$1000,G151,$E$2:$E$1000) -> 0

Sheet Feb
A1: Date | B1: Asset Manager | C1: Investment | D1: Company | E1: Value | G1: Summary | H1: Value | I1: Lists | N1: List | O1: Value
A2: ='2024 Summary'!A4 -> 45323 | G2: {=_xlfn._xlws.SORT(_xlfn.UNIQUE(D2:D1000))} -> 0 | H2: =SUMIF($D$2:$D$1000,G2,$E$2:$E$1000) -> 0 | N2: UN Blacklist 2023 | O2: =SUMIF($I$2:$I$1000,"*UN Blacklist 2023*",$H$2:$H$1000) -> 0
H3: =SUMIF($D$2:$D$1000,G3,$E$2:$E$1000) -> 0 | N3: UN Blacklist 2025 | O3: =SUMIF($I$2:$I$1000,"*UN Blacklist 2025*",$H$2:$H$1000) -> 0
H4: =SUMIF($D$2:$D$1000,G4,$E$2:$E$1000) -> 0 | N4: AFSC Divestment List 2025 | O4: =SUMIF($I$2:$I$971000,"*AFSC Divestment List 2025*",$H$2:$H$1000) -> 0
H5: =SUMIF($D$2:$D$1000,G5,$E$2:$E$1000) -> 0 | N5: WhoProfits | O5: =SUMIF($I$2:$I$1000,"*Who Profits*",$H$2:$H$1000) -> 0
H6: =SUMIF($D$2:$D$1000,G6,$E$2:$E$1000) -> 0
H7: =SUMIF($D$2:$D$1000,G7,$E$2:$E$1000) -> 0 | N7: Bank | O7: Value
H8: =SUMIF($D$2:$D$1000,G8,$E$2:$E$1000) -> 0 | N8: Danske Bank | O8: =SUMIF($B$2:$B$1000,"*Danske Bank*",$E$2:$E$1000) -> 0
H9: =SUMIF($D$2:$D$1000,G9,$E$2:$E$1000) -> 0 | N9: Jyske Bank | O9: =SUMIF($B$2:$B$1000,"*Jyske Bank*",$E$2:$E$1000) -> 0
H10: =SUMIF($D$2:$D$1000,G10,$E$2:$E$1000) -> 0 | N10: SEB | O10: =SUMIF($B$2:$B$1000,"*SEB*",$E$2:$E$1000) -> 0
H11: =SUMIF($D$2:$D$1000,G11,$E$2:$E$1000) -> 0
H12: =SUMIF($D$2:$D$1000,G12,$E$2:$E$1000) -> 0 | N12: Total
H13: =SUMIF($D$2:$D$1000,G13,$E$2:$E$1000) -> 0 | N13: =SUM(E2:E1000) -> 0
H14: =SUMIF($D$2:$D$1000,G14,$E$2:$E$1000) -> 0
H15: =SUMIF($D$2:$D$1000,G15,$E$2:$E$1000) -> 0
H16: =SUMIF($D$2:$D$1000,G16,$E$2:$E$1000) -> 0
H17: =SUMIF($D$2:$D$1000,G17,$E$2:$E$1000) -> 0
H18: =SUMIF($D$2:$D$1000,G18,$E$2:$E$1000) -> 0
H19: =SUMIF($D$2:$D$1000,G19,$E$2:$E$1000) -> 0
H20: =SUMIF($D$2:$D$1000,G20,$E$2:$E$1000) -> 0
H21: =SUMIF($D$2:$D$1000,G21,$E$2:$E$1000) -> 0
H22: =SUMIF($D$2:$D$1000,G22,$E$2:$E$1000) -> 0
H23: =SUMIF($D$2:$D$1000,G23,$E$2:$E$1000) -> 0
H24: =SUMIF($D$2:$D$1000,G24,$E$2:$E$1000) -> 0
H25: =SUMIF($D$2:$D$1000,G25,$E$2:$E$1000) -> 0
... H151: =SUMIF($D$2:$D$1000,G151,$E$2:$E$1000) -> 0

Sheet Mar
A1: Date | B1: Asset Manager | C1: Investment | D1: Company | E1: Value | G1: Summary | H1: Value | I1: Lists | N1: List | O1: Value
A2: ='2024 Summary'!A5 -> 45354 | G2: {=_xlfn._xlws.SORT(_xlfn.UNIQUE(D2:D1000))} -> 0 | H2: =SUMIF($D$2:$D$1000,G2,$E$2:$E$1000) -> 0 | N2: UN Blacklist 2023 | O2: =SUMIF($I$2:$I$1000,"*UN Blacklist 2023*",$H$2:$H$1000) -> 0
H3: =SUMIF($D$2:$D$1000,G3,$E$2:$E$1000) -> 0 | N3: UN Blacklist 2025 | O3: =SUMIF($I$2:$I$1000,"*UN Blacklist 2025*",$H$2:$H$1000) -> 0
H4: =SUMIF($D$2:$D$1000,G4,$E$2:$E$1000) -> 0 | N4: AFSC Divestment List 2025 | O4: =SUMIF($I$2:$I$971000,"*AFSC Divestment List 2025*",$H$2:$H$1000) -> 0
H5: =SUMIF($D$2:$D$1000,G5,$E$2:$E$1000) -> 0 | N5: WhoProfits | O5: =SUMIF($I$2:$I$1000,"*Who Profits*",$H$2:$H$1000) -> 0
H6: =SUMIF($D$2:$D$1000,G6,$E$2:$E$1000) -> 0
H7: =SUMIF($D$2:$D$1000,G7,$E$2:$E$1000) -> 0 | N7: Bank | O7: Value
H8: =SUMIF($D$2:$D$1000,G8,$E$2:$E$1000) -> 0 | N8: Danske Bank | O8: =SUMIF($B$2:$B$1000,"*Danske Bank*",$E$2:$E$1000) -> 0
H9: =SUMIF($D$2:$D$1000,G9,$E$2:$E$1000) -> 0 | N9: Jyske Bank | O9: =SUMIF($B$2:$B$1000,"*Jyske Bank*",$E$2:$E$1000) -> 0
H10: =SUMIF($D$2:$D$1000,G10,$E$2:$E$1000) -> 0 | N10: SEB | O10: =SUMIF($B$2:$B$1000,"*SEB*",$E$2:$E$1000) -> 0
H11: =SUMIF($D$2:$D$1000,G11,$E$2:$E$1000) -> 0
H12: =SUMIF($D$2:$D$1000,G12,$E$2:$E$1000) -> 0 | N12: Total
H13: =SUMIF($D$2:$D$1000,G13,$E$2:$E$1000) -> 0 | N13: =SUM(E2:E1000) -> 0
H14: =SUMIF($D$2:$D$1000,G14,$E$2:$E$1000) -> 0
H15: =SUMIF($D$2:$D$1000,G15,$E$2:$E$1000) -> 0
H16: =SUMIF($D$2:$D$1000,G16,$E$2:$E$1000) -> 0
H17: =SUMIF($D$2:$D$1000,G17,$E$2:$E$1000) -> 0
H18: =SUMIF($D$2:$D$1000,G18,$E$2:$E$1000) -> 0
H19: =SUMIF($D$2:$D$1000,G19,$E$2:$E$1000) -> 0
H20: =SUMIF($D$2:$D$1000,G20,$E$2:$E$1000) -> 0
H21: =SUMIF($D$2:$D$1000,G21,$E$2:$E$1000) -> 0
H22: =SUMIF($D$2:$D$1000,G22,$E$2:$E$1000) -> 0
H23: =SUMIF($D$2:$D$1000,G23,$E$2:$E$1000) -> 0
H24: =SUMIF($D$2:$D$1000,G24,$E$2:$E$1000) -> 0
H25: =SUMIF($D$2:$D$1000,G25,$E$2:$E$1000) -> 0
... H151: =SUMIF($D$2:$D$1000,G151,$E$2:$E$1000) -> 0

Sheet Apr
A1: Date | B1: Asset Manager | C1: Investment | D1: Company | E1: Value | G1: Summary | H1: Value | I1: Lists | N1: List | O1: Value
A2: ='2024 Summary'!A6 -> 45385 | G2: {=_xlfn._xlws.SORT(_xlfn.UNIQUE(D2:D1000))} -> 0 | H2: =SUMIF($D$2:$D$1000,G2,$E$2:$E$1000) -> 0 | N2: UN Blacklist 2023 | O2: =SUMIF($I$2:$I$1000,"*UN Blacklist 2023*",$H$2:$H$1000) -> 0
H3: =SUMIF($D$2:$D$1000,G3,$E$2:$E$1000) -> 0 | N3: UN Blacklist 2025 | O3: =SUMIF($I$2:$I$1000,"*UN Blacklist 2025*",$H$2:$H$1000) -> 0
H4: =SUMIF($D$2:$D$1000,G4,$E$2:$E$1000) -> 0 | N4: AFSC Divestment List 2025 | O4: =SUMIF($I$2:$I$971000,"*AFSC Divestment List 2025*",$H$2:$H$1000) -> 0
H5: =SUMIF($D$2:$D$1000,G5,$E$2:$E$1000) -> 0 | N5: WhoProfits | O5: =SUMIF($I$2:$I$1000,"*Who Profits*",$H$2:$H$1000) -> 0
H6: =SUMIF($D$2:$D$1000,G6,$E$2:$E$1000) -> 0
H7: =SUMIF($D$2:$D$1000,G7,$E$2:$E$1000) -> 0 | N7: Bank | O7: Value
H8: =SUMIF($D$2:$D$1000,G8,$E$2:$E$1000) -> 0 | N8: Danske Bank | O8: =SUMIF($B$2:$B$1000,"*Danske Bank*",$E$2:$E$1000) -> 0
H9: =SUMIF($D$2:$D$1000,G9,$E$2:$E$1000) -> 0 | N9: Jyske Bank | O9: =SUMIF($B$2:$B$1000,"*Jyske Bank*",$E$2:$E$1000) -> 0
H10: =SUMIF($D$2:$D$1000,G10,$E$2:$E$1000) -> 0 | N10: SEB | O10: =SUMIF($B$2:$B$1000,"*SEB*",$E$2:$E$1000) -> 0
H11: =SUMIF($D$2:$D$1000,G11,$E$2:$E$1000) -> 0
H12: =SUMIF($D$2:$D$1000,G12,$E$2:$E$1000) -> 0 | N12: Total
H13: =SUMIF($D$2:$D$1000,G13,$E$2:$E$1000) -> 0 | N13: =SUM(E2:E1000) -> 0
H14: =SUMIF($D$2:$D$1000,G14,$E$2:$E$1000) -> 0
H15: =SUMIF($D$2:$D$1000,G15,$E$2:$E$1000) -> 0
H16: =SUMIF($D$2:$D$1000,G16,$E$2:$E$1000) -> 0
H17: =SUMIF($D$2:$D$1000,G17,$E$2:$E$1000) -> 0
H18: =SUMIF($D$2:$D$1000,G18,$E$2:$E$1000) -> 0
H19: =SUMIF($D$2:$D$1000,G19,$E$2:$E$1000) -> 0
H20: =SUMIF($D$2:$D$1000,G20,$E$2:$E$1000) -> 0
H21: =SUMIF($D$2:$D$1000,G21,$E$2:$E$1000) -> 0
H22: =SUMIF($D$2:$D$1000,G22,$E$2:$E$1000) -> 0
H23: =SUMIF($D$2:$D$1000,G23,$E$2:$E$1000) -> 0
H24: =SUMIF($D$2:$D$1000,G24,$E$2:$E$1000) -> 0
H25: =SUMIF($D$2:$D$1000,G25,$E$2:$E$1000) -> 0
... H151: =SUMIF($D$2:$D$1000,G151,$E$2:$E$1000) -> 0

Sheet May
A1: Date | B1: Asset Manager | C1: Investment | D1: Company | E1: Value | G1: Summary | H1: Value | I1: Lists | N1: List | O1: Value
A2: ='2024 Summary'!A7 -> 45416 | G2: {=_xlfn._xlws.SORT(_xlfn.UNIQUE(D2:D1000))} -> 0 | H2: =SUMIF($D$2:$D$1000,G2,$E$2:$E$1000) -> 0 | N2: UN Blacklist 2023 | O2: =SUMIF($I$2:$I$1000,"*UN Blacklist 2023*",$H$2:$H$1000) -> 0
H3: =SUMIF($D$2:$D$1000,G3,$E$2:$E$1000) -> 0 | N3: UN Blacklist 2025 | O3: =SUMIF($I$2:$I$1000,"*UN Blacklist 2025*",$H$2:$H$1000) -> 0
H4: =SUMIF($D$2:$D$1000,G4,$E$2:$E$1000) -> 0 | N4: AFSC Divestment List 2025 | O4: =SUMIF($I$2:$I$971000,"*AFSC Divestment List 2025*",$H$2:$H$1000) -> 0
H5: =SUMIF($D$2:$D$1000,G5,$E$2:$E$1000) -> 0 | N5: WhoProfits | O5: =SUMIF($I$2:$I$1000,"*Who Profits*",$H$2:$H$1000) -> 0
H6: =SUMIF($D$2:$D$1000,G6,$E$2:$E$1000) -> 0
H7: =SUMIF($D$2:$D$1000,G7,$E$2:$E$1000) -> 0 | N7: Bank | O7: Value
H8: =SUMIF($D$2:$D$1000,G8,$E$2:$E$1000) -> 0 | N8: Danske Bank | O8: =SUMIF($B$2:$B$1000,"*Danske Bank*",$E$2:$E$1000) -> 0
H9: =SUMIF($D$2:$D$1000,G9,$E$2:$E$1000) -> 0 | N9: Jyske Bank | O9: =SUMIF($B$2:$B$1000,"*Jyske Bank*",$E$2:$E$1000) -> 0
H10: =SUMIF($D$2:$D$1000,G10,$E$2:$E$1000) -> 0 | N10: SEB | O10: =SUMIF($B$2:$B$1000,"*SEB*",$E$2:$E$1000) -> 0
H11: =SUMIF($D$2:$D$1000,G11,$E$2:$E$1000) -> 0
H12: =SUMIF($D$2:$D$1000,G12,$E$2:$E$1000) -> 0 | N12: Total
H13: =SUMIF($D$2:$D$1000,G13,$E$2:$E$1000) -> 0 | N13: =SUM(E2:E1000) -> 0
H14: =SUMIF($D$2:$D$1000,G14,$E$2:$E$1000) -> 0
H15: =SUMIF($D$2:$D$1000,G15,$E$2:$E$1000) -> 0
H16: =SUMIF($D$2:$D$1000,G16,$E$2:$E$1000) -> 0
H17: =SUMIF($D$2:$D$1000,G17,$E$2:$E$1000) -> 0
H18: =SUMIF($D$2:$D$1000,G18,$E$2:$E$1000) -> 0
H19: =SUMIF($D$2:$D$1000,G19,$E$2:$E$1000) -> 0
H20: =SUMIF($D$2:$D$1000,G20,$E$2:$E$1000) -> 0
H21: =SUMIF($D$2:$D$1000,G21,$E$2:$E$1000) -> 0
H22: =SUMIF($D$2:$D$1000,G22,$E$2:$E$1000) -> 0
H23: =SUMIF($D$2:$D$1000,G23,$E$2:$E$1000) -> 0
H24: =SUMIF($D$2:$D$1000,G24,$E$2:$E$1000) -> 0
H25: =SUMIF($D$2:$D$1000,G25,$E$2:$E$1000) -> 0
... H151: =SUMIF($D$2:$D$1000,G151,$E$2:$E$1000) -> 0

Sheet Jun
A1: Date | B1: Asset Manager | C1: Investment | D1: Company | E1: Value | G1: Summary | H1: Value | I1: Lists | N1: List | O1: Value
A2: ='2024 Summary'!A8 -> 45447 | G2: {=_xlfn._xlws.SORT(_xlfn.UNIQUE(D2:D1000))} -> 0 | H2: =SUMIF($D$2:$D$1000,G2,$E$2:$E$1000) -> 0 | N2: UN Blacklist 2023 | O2: =SUMIF($I$2:$I$1000,"*UN Blacklist 2023*",$H$2:$H$1000) -> 0
H3: =SUMIF($D$2:$D$1000,G3,$E$2:$E$1000) -> 0 | N3: UN Blacklist 2025 | O3: =SUMIF($I$2:$I$1000,"*UN Blacklist 2025*",$H$2:$H$1000) -> 0
H4: =SUMIF($D$2:$D$1000,G4,$E$2:$E$1000) -> 0 | N4: AFSC Divestment List 2025 | O4: =SUMIF($I$2:$I$971000,"*AFSC Divestment List 2025*",$H$2:$H$1000) -> 0
H5: =SUMIF($D$2:$D$1000,G5,$E$2:$E$1000) -> 0 | N5: WhoProfits | O5: =SUMIF($I$2:$I$1000,"*Who Profits*",$H$2:$H$1000) -> 0
H6: =SUMIF($D$2:$D$1000,G6,$E$2:$E$1000) -> 0
H7: =SUMIF($D$2:$D$1000,G7,$E$2:$E$1000) -> 0 | N7: Bank | O7: Value
H8: =SUMIF($D$2:$D$1000,G8,$E$2:$E$1000) -> 0 | N8: Danske Bank | O8: =SUMIF($B$2:$B$1000,"*Danske Bank*",$E$2:$E$1000) -> 0
H9: =SUMIF($D$2:$D$1000,G9,$E$2:$E$1000) -> 0 | N9: Jyske Bank | O9: =SUMIF($B$2:$B$1000,"*Jyske Bank*",$E$2:$E$1000) -> 0
H10: =SUMIF($D$2:$D$1000,G10,$E$2:$E$1000) -> 0 | N10: SEB | O10: =SUMIF($B$2:$B$1000,"*SEB*",$E$2:$E$1000) -> 0
H11: =SUMIF($D$2:$D$1000,G11,$E$2:$E$1000) -> 0
H12: =SUMIF($D$2:$D$1000,G12,$E$2:$E$1000) -> 0 | N12: Total
H13: =SUMIF($D$2:$D$1000,G13,$E$2:$E$1000) -> 0 | N13: =SUM(E2:E1000) -> 0
H14: =SUMIF($D$2:$D$1000,G14,$E$2:$E$1000) -> 0
H15: =SUMIF($D$2:$D$1000,G15,$E$2:$E$1000) -> 0
H16: =SUMIF($D$2:$D$1000,G16,$E$2:$E$1000) -> 0
H17: =SUMIF($D$2:$D$1000,G17,$E$2:$E$1000) -> 0
H18: =SUMIF($D$2:$D$1000,G18,$E$2:$E$1000) -> 0
H19: =SUMIF($D$2:$D$1000,G19,$E$2:$E$1000) -> 0
H20: =SUMIF($D$2:$D$1000,G20,$E$2:$E$1000) -> 0
H21: =SUMIF($D$2:$D$1000,G21,$E$2:$E$1000) -> 0
H22: =SUMIF($D$2:$D$1000,G22,$E$2:$E$1000) -> 0
H23: =SUMIF($D$2:$D$1000,G23,$E$2:$E$1000) -> 0
H24: =SUMIF($D$2:$D$1000,G24,$E$2:$E$1000) -> 0
H25: =SUMIF($D$2:$D$1000,G25,$E$2:$E$1000) -> 0
... H151: =SUMIF($D$2:$D$1000,G151,$E$2:$E$1000) -> 0

Sheet Jul
A1: Date | B1: Asset Manager | C1: Investment | D1: Company | E1: Value | G1: Summary | H1: Value | I1: Lists | N1: List | O1: Value
A2: ='2024 Summary'!A9 -> 45478 | G2: {=_xlfn._xlws.SORT(_xlfn.UNIQUE(D2:D1000))} -> 0 | H2: =SUMIF($D$2:$D$1000,G2,$E$2:$E$1000) -> 0 | N2: UN Blacklist 2023 | O2: =SUMIF($I$2:$I$1000,"*UN Blacklist 2023*",$H$2:$H$1000) -> 0
H3: =SUMIF($D$2:$D$1000,G3,$E$2:$E$1000) -> 0 | N3: UN Blacklist 2025 | O3: =SUMIF($I$2:$I$1000,"*UN Blacklist 2025*",$H$2:$H$1000) -> 0
H4: =SUMIF($D$2:$D$1000,G4,$E$2:$E$1000) -> 0 | N4: AFSC Divestment List 2025 | O4: =SUMIF($I$2:$I$971000,"*AFSC Divestment List 2025*",$H$2:$H$1000) -> 0
H5: =SUMIF($D$2:$D$1000,G5,$E$2:$E$1000) -> 0 | N5: WhoProfits | O5: =SUMIF($I$2:$I$1000,"*Who Profits*",$H$2:$H$1000) -> 0
H6: =SUMIF($D$2:$D$1000,G6,$E$2:$E$1000) -> 0
H7: =SUMIF($D$2:$D$1000,G7,$E$2:$E$1000) -> 0 | N7: Bank | O7: Value
H8: =SUMIF($D$2:$D$1000,G8,$E$2:$E$1000) -> 0 | N8: Danske Bank | O8: =SUMIF($B$2:$B$1000,"*Danske Bank*",$E$2:$E$1000) -> 0
H9: =SUMIF($D$2:$D$1000,G9,$E$2:$E$1000) -> 0 | N9: Jyske Bank | O9: =SUMIF($B$2:$B$1000,"*Jyske Bank*",$E$2:$E$1000) -> 0
H10: =SUMIF($D$2:$D$1000,G10,$E$2:$E$1000) -> 0 | N10: SEB | O10: =SUMIF($B$2:$B$1000,"*SEB*",$E$2:$E$1000) -> 0
H11: =SUMIF($D$2:$D$1000,G11,$E$2:$E$1000) -> 0
H12: =SUMIF($D$2:$D$1000,G12,$E$2:$E$1000) -> 0 | N12: Total
H13: =SUMIF($D$2:$D$1000,G13,$E$2:$E$1000) -> 0 | N13: =SUM(E2:E1000) -> 0
H14: =SUMIF($D$2:$D$1000,G14,$E$2:$E$1000) -> 0
H15: =SUMIF($D$2:$D$1000,G15,$E$2:$E$1000) -> 0
H16: =SUMIF($D$2:$D$1000,G16,$E$2:$E$1000) -> 0
H17: =SUMIF($D$2:$D$1000,G17,$E$2:$E$1000) -> 0
H18: =SUMIF($D$2:$D$1000,G18,$E$2:$E$1000) -> 0
H19: =SUMIF($D$2:$D$1000,G19,$E$2:$E$1000) -> 0
H20: =SUMIF($D$2:$D$1000,G20,$E$2:$E$1000) -> 0
H21: =SUMIF($D$2:$D$1000,G21,$E$2:$E$1000) -> 0
H22: =SUMIF($D$2:$D$1000,G22,$E$2:$E$1000) -> 0
H23: =SUMIF($D$2:$D$1000,G23,$E$2:$E$1000) -> 0
H24: =SUMIF($D$2:$D$1000,G24,$E$2:$E$1000) -> 0
H25: =SUMIF($D$2:$D$1000,G25,$E$2:$E$1000) -> 0
... H151: =SUMIF($D$2:$D$1000,G151,$E$2:$E$1000) -> 0

Sheet Aug
A1: Date | B1: Asset Manager | C1: Investment | D1: Company | E1: Value | G1: Summary | H1: Value | I1: Lists | N1: List | O1: Value
A2: ='2024 Summary'!A10 -> 45509 | G2: {=_xlfn._xlws.SORT(_xlfn.UNIQUE(D2:D1000))} -> 0 | H2: =SUMIF($D$2:$D$1000,G2,$E$2:$E$1000) -> 0 | N2: UN Blacklist 2023 | O2: =SUMIF($I$2:$I$1000,"*UN Blacklist 2023*",$H$2:$H$1000) -> 0
H3: =SUMIF($D$2:$D$1000,G3,$E$2:$E$1000) -> 0 | N3: UN Blacklist 2025 | O3: =SUMIF($I$2:$I$1000,"*UN Blacklist 2025*",$H$2:$H$1000) -> 0
H4: =SUMIF($D$2:$D$1000,G4,$E$2:$E$1000) -> 0 | N4: AFSC Divestment List 2025 | O4: =SUMIF($I$2:$I$971000,"*AFSC Divestment List 2025*",$H$2:$H$1000) -> 0
H5: =SUMIF($D$2:$D$1000,G5,$E$2:$E$1000) -> 0 | N5: WhoProfits | O5: =SUMIF($I$2:$I$1000,"*Who Profits*",$H$2:$H$1000) -> 0
H6: =SUMIF($D$2:$D$1000,G6,$E$2:$E$1000) -> 0
H7: =SUMIF($D$2:$D$1000,G7,$E$2:$E$1000) -> 0 | N7: Bank | O7: Value
H8: =SUMIF($D$2:$D$1000,G8,$E$2:$E$1000) -> 0 | N8: Danske Bank | O8: =SUMIF($B$2:$B$1000,"*Danske Bank*",$E$2:$E$1000) -> 0
H9: =SUMIF($D$2:$D$1000,G9,$E$2:$E$1000) -> 0 | N9: Jyske Bank | O9: =SUMIF($B$2:$B$1000,"*Jyske Bank*",$E$2:$E$1000) -> 0
H10: =SUMIF($D$2:$D$1000,G10,$E$2:$E$1000) -> 0 | N10: SEB | O10: =SUMIF($B$2:$B$1000,"*SEB*",$E$2:$E$1000) -> 0
H11: =SUMIF($D$2:$D$1000,G11,$E$2:$E$1000) -> 0
H12: =SUMIF($D$2:$D$1000,G12,$E$2:$E$1000) -> 0 | N12: Total
H13: =SUMIF($D$2:$D$1000,G13,$E$2:$E$1000) -> 0 | N13: =SUM(E2:E1000) -> 0
H14: =SUMIF($D$2:$D$1000,G14,$E$2:$E$1000) -> 0
H15: =SUMIF($D$2:$D$1000,G15,$E$2:$E$1000) -> 0
H16: =SUMIF($D$2:$D$1000,G16,$E$2:$E$1000) -> 0
H17: =SUMIF($D$2:$D$1000,G17,$E$2:$E$1000) -> 0
H18: =SUMIF($D$2:$D$1000,G18,$E$2:$E$1000) -> 0
H19: =SUMIF($D$2:$D$1000,G19,$E$2:$E$1000) -> 0
H20: =SUMIF($D$2:$D$1000,G20,$E$2:$E$1000) -> 0
H21: =SUMIF($D$2:$D$1000,G21,$E$2:$E$1000) -> 0
H22: =SUMIF($D$2:$D$1000,G22,$E$2:$E$1000) -> 0
H23: =SUMIF($D$2:$D$1000,G23,$E$2:$E$1000) -> 0
H24: =SUMIF($D$2:$D$1000,G24,$E$2:$E$1000) -> 0
H25: =SUMIF($D$2:$D$1000,G25,$E$2:$E$1000) -> 0
... H151: =SUMIF($D$2:$D$1000,G151,$E$2:$E$1000) -> 0

Sheet Sep
A1: Date | B1: Asset Manager | C1: Investment | D1: Company | E1: Value | G1: Summary | H1: Value | I1: Lists | N1: List | O1: Value
A2: ='2024 Summary'!A11 -> 45540 | G2: {=_xlfn._xlws.SORT(_xlfn.UNIQUE(D2:D1000))} -> 0 | H2: =SUMIF($D$2:$D$1000,G2,$E$2:$E$1000) -> 0 | N2: UN Blacklist 2023 | O2: =SUMIF($I$2:$I$1000,"*UN Blacklist 2023*",$H$2:$H$1000) -> 0
H3: =SUMIF($D$2:$D$1000,G3,$E$2:$E$1000) -> 0 | N3: UN Blacklist 2025 | O3: =SUMIF($I$2:$I$1000,"*UN Blacklist 2025*",$H$2:$H$1000) -> 0
H4: =SUMIF($D$2:$D$1000,G4,$E$2:$E$1000) -> 0 | N4: AFSC Divestment List 2025 | O4: =SUMIF($I$2:$I$971000,"*AFSC Divestment List 2025*",$H$2:$H$1000) -> 0
H5: =SUMIF($D$2:$D$1000,G5,$E$2:$E$1000) -> 0 | N5: WhoProfits | O5: =SUMIF($I$2:$I$1000,"*Who Profits*",$H$2:$H$1000) -> 0
H6: =SUMIF($D$2:$D$1000,G6,$E$2:$E$1000) -> 0
H7: =SUMIF($D$2:$D$1000,G7,$E$2:$E$1000) -> 0 | N7: Bank | O7: Value
H8: =SUMIF($D$2:$D$1000,G8,$E$2:$E$1000) -> 0 | N8: Danske Bank | O8: =SUMIF($B$2:$B$1000,"*Danske Bank*",$E$2:$E$1000) -> 0
H9: =SUMIF($D$2:$D$1000,G9,$E$2:$E$1000) -> 0 | N9: Jyske Bank | O9: =SUMIF($B$2:$B$1000,"*Jyske Bank*",$E$2:$E$1000) -> 0
H10: =SUMIF($D$2:$D$1000,G10,$E$2:$E$1000) -> 0 | N10: SEB | O10: =SUMIF($B$2:$B$1000,"*SEB*",$E$2:$E$1000) -> 0
H11: =SUMIF($D$2:$D$1000,G11,$E$2:$E$1000) -> 0
H12: =SUMIF($D$2:$D$1000,G12,$E$2:$E$1000) -> 0 | N12: Total
H13: =SUMIF($D$2:$D$1000,G13,$E$2:$E$1000) -> 0 | N13: =SUM(E2:E1000) -> 0
H14: =SUMIF($D$2:$D$1000,G14,$E$2:$E$1000) -> 0
H15: =SUMIF($D$2:$D$1000,G15,$E$2:$E$1000) -> 0
H16: =SUMIF($D$2:$D$1000,G16,$E$2:$E$1000) -> 0
H17: =SUMIF($D$2:$D$1000,G17,$E$2:$E$1000) -> 0
H18: =SUMIF($D$2:$D$1000,G18,$E$2:$E$1000) -> 0
H19: =SUMIF($D$2:$D$1000,G19,$E$2:$E$1000) -> 0
H20: =SUMIF($D$2:$D$1000,G20,$E$2:$E$1000) -> 0
H21: =SUMIF($D$2:$D$1000,G21,$E$2:$E$1000) -> 0
H22: =SUMIF($D$2:$D$1000,G22,$E$2:$E$1000) -> 0
H23: =SUMIF($D$2:$D$1000,G23,$E$2:$E$1000) -> 0
H24: =SUMIF($D$2:$D$1000,G24,$E$2:$E$1000) -> 0
H25: =SUMIF($D$2:$D$1000,G25,$E$2:$E$1000) -> 0
... H151: =SUMIF($D$2:$D$1000,G151,$E$2:$E$1000) -> 0

Sheet Oct
A1: Date | B1: Asset Manager | C1: Investment | D1: Company | E1: Value | G1: Summary | H1: Value | I1: Lists | N1: List | O1: Value
A2: ='2024 Summary'!A12 -> 45571 | G2: {=_xlfn._xlws.SORT(_xlfn.UNIQUE(D2:D1000))} -> 0 | H2: =SUMIF($D$2:$D$1000,G2,$E$2:$E$1000) -> 0 | N2: UN Blacklist 2023 | O2: =SUMIF($I$2:$I$1000,"*UN Blacklist 2023*",$H$2:$H$1000) -> 0
H3: =SUMIF($D$2:$D$1000,G3,$E$2:$E$1000) -> 0 | N3: UN Blacklist 2025 | O3: =SUMIF($I$2:$I$1000,"*UN Blacklist 2025*",$H$2:$H$1000) -> 0
H4: =SUMIF($D$2:$D$1000,G4,$E$2:$E$1000) -> 0 | N4: AFSC Divestment List 2025 | O4: =SUMIF($I$2:$I$971000,"*AFSC Divestment List 2025*",$H$2:$H$1000) -> 0
H5: =SUMIF($D$2:$D$1000,G5,$E$2:$E$1000) -> 0 | N5: WhoProfits | O5: =SUMIF($I$2:$I$1000,"*Who Profits*",$H$2:$H$1000) -> 0
H6: =SUMIF($D$2:$D$1000,G6,$E$2:$E$1000) -> 0
H7: =SUMIF($D$2:$D$1000,G7,$E$2:$E$1000) -> 0 | N7: Bank | O7: Value
H8: =SUMIF($D$2:$D$1000,G8,$E$2:$E$1000) -> 0 | N8: Danske Bank | O8: =SUMIF($B$2:$B$1000,"*Danske Bank*",$E$2:$E$1000) -> 0
H9: =SUMIF($D$2:$D$1000,G9,$E$2:$E$1000) -> 0 | N9: Jyske Bank | O9: =SUMIF($B$2:$B$1000,"*Jyske Bank*",$E$2:$E$1000) -> 0
H10: =SUMIF($D$2:$D$1000,G10,$E$2:$E$1000) -> 0 | N10: SEB | O10: =SUMIF($B$2:$B$1000,"*SEB*",$E$2:$E$1000) -> 0
H11: =SUMIF($D$2:$D$1000,G11,$E$2:$E$1000) -> 0
H12: =SUMIF($D$2:$D$1000,G12,$E$2:$E$1000) -> 0 | N12: Total
H13: =SUMIF($D$2:$D$1000,G13,$E$2:$E$1000) -> 0 | N13: =SUM(E2:E1000) -> 0
H14: =SUMIF($D$2:$D$1000,G14,$E$2:$E$1000) -> 0
H15: =SUMIF($D$2:$D$1000,G15,$E$2:$E$1000) -> 0
H16: =SUMIF($D$2:$D$1000,G16,$E$2:$E$1000) -> 0
H17: =SUMIF($D$2:$D$1000,G17,$E$2:$E$1000) -> 0
H18: =SUMIF($D$2:$D$1000,G18,$E$2:$E$1000) -> 0
H19: =SUMIF($D$2:$D$1000,G19,$E$2:$E$1000) -> 0
H20: =SUMIF($D$2:$D$1000,G20,$E$2:$E$1000) -> 0
H21: =SUMIF($D$2:$D$1000,G21,$E$2:$E$1000) -> 0
H22: =SUMIF($D$2:$D$1000,G22,$E$2:$E$1000) -> 0
H23: =SUMIF($D$2:$D$1000,G23,$E$2:$E$1000) -> 0
H24: =SUMIF($D$2:$D$1000,G24,$E$2:$E$1000) -> 0
H25: =SUMIF($D$2:$D$1000,G25,$E$2:$E$1000) -> 0
... H151: =SUMIF($D$2:$D$1000,G151,$E$2:$E$1000) -> 0

Sheet Nov
A1: Date | B1: Asset Manager | C1: Investment | D1: Company | E1: Value | G1: Summary | H1: Value | I1: Lists | N1: List | O1: Value
A2: ='2024 Summary'!A13 -> 45602 | G2: {=_xlfn._xlws.SORT(_xlfn.UNIQUE(D2:D1000))} -> 0 | H2: =SUMIF($D$2:$D$1000,G2,$E$2:$E$1000) -> 0 | N2: UN Blacklist 2023 | O2: =SUMIF($I$2:$I$1000,"*UN Blacklist 2023*",$H$2:$H$1000) -> 0
H3: =SUMIF($D$2:$D$1000,G3,$E$2:$E$1000) -> 0 | N3: UN Blacklist 2025 | O3: =SUMIF($I$2:$I$1000,"*UN Blacklist 2025*",$H$2:$H$1000) -> 0
H4: =SUMIF($D$2:$D$1000,G4,$E$2:$E$1000) -> 0 | N4: AFSC Divestment List 2025 | O4: =SUMIF($I$2:$I$971000,"*AFSC Divestment List 2025*",$H$2:$H$1000) -> 0
H5: =SUMIF($D$2:$D$1000,G5,$E$2:$E$1000) -> 0 | N5: WhoProfits | O5: =SUMIF($I$2:$I$1000,"*Who Profits*",$H$2:$H$1000) -> 0
H6: =SUMIF($D$2:$D$1000,G6,$E$2:$E$1000) -> 0
H7: =SUMIF($D$2:$D$1000,G7,$E$2:$E$1000) -> 0 | N7: Bank | O7: Value
H8: =SUMIF($D$2:$D$1000,G8,$E$2:$E$1000) -> 0 | N8: Danske Bank | O8: =SUMIF($B$2:$B$1000,"*Danske Bank*",$E$2:$E$1000) -> 0
H9: =SUMIF($D$2:$D$1000,G9,$E$2:$E$1000) -> 0 | N9: Jyske Bank | O9: =SUMIF($B$2:$B$1000,"*Jyske Bank*",$E$2:$E$1000) -> 0
H10: =SUMIF($D$2:$D$1000,G10,$E$2:$E$1000) -> 0 | N10: SEB | O10: =SUMIF($B$2:$B$1000,"*SEB*",$E$2:$E$1000) -> 0
H11: =SUMIF($D$2:$D$1000,G11,$E$2:$E$1000) -> 0
H12: =SUMIF($D$2:$D$1000,G12,$E$2:$E$1000) -> 0 | N12: Total
H13: =SUMIF($D$2:$D$1000,G13,$E$2:$E$1000) -> 0 | N13: =SUM(E2:E1000) -> 0
H14: =SUMIF($D$2:$D$1000,G14,$E$2:$E$1000) -> 0
H15: =SUMIF($D$2:$D$1000,G15,$E$2:$E$1000) -> 0
H16: =SUMIF($D$2:$D$1000,G16,$E$2:$E$1000) -> 0
H17: =SUMIF($D$2:$D$1000,G17,$E$2:$E$1000) -> 0
H18: =SUMIF($D$2:$D$1000,G18,$E$2:$E$1000) -> 0
H19: =SUMIF($D$2:$D$1000,G19,$E$2:$E$1000) -> 0
H20: =SUMIF($D$2:$D$1000,G20,$E$2:$E$1000) -> 0
H21: =SUMIF($D$2:$D$1000,G21,$E$2:$E$1000) -> 0
H22: =SUMIF($D$2:$D$1000,G22,$E$2:$E$1000) -> 0
H23: =SUMIF($D$2:$D$1000,G23,$E$2:$E$1000) -> 0
H24: =SUMIF($D$2:$D$1000,G24,$E$2:$E$1000) -> 0
H25: =SUMIF($D$2:$D$1000,G25,$E$2:$E$1000) -> 0
... H151: =SUMIF($D$2:$D$1000,G151,$E$2:$E$1000) -> 0

Sheet Dec
A1: Date | B1: Asset Manager | C1: Investment | D1: Company | E1: Value | G1: Summary | H1: Value | I1: Lists | N1: List | O1: Value
A2: ='2024 Summary'!A14 -> 45633 | G2: {=_xlfn._xlws.SORT(_xlfn.UNIQUE(D2:D1000))} -> 0 | H2: =SUMIF($D$2:$D$1000,G2,$E$2:$E$1000) -> 0 | N2: UN Blacklist 2023 | O2: =SUMIF($I$2:$I$1000,"*UN Blacklist 2023*",$H$2:$H$1000) -> 0
H3: =SUMIF($D$2:$D$1000,G3,$E$2:$E$1000) -> 0 | N3: UN Blacklist 2025 | O3: =SUMIF($I$2:$I$1000,"*UN Blacklist 2025*",$H$2:$H$1000) -> 0
H4: =SUMIF($D$2:$D$1000,G4,$E$2:$E$1000) -> 0 | N4: AFSC Divestment List 2025 | O4: =SUMIF($I$2:$I$971000,"*AFSC Divestment List 2025*",$H$2:$H$1000) -> 0
H5: =SUMIF($D$2:$D$1000,G5,$E$2:$E$1000) -> 0 | N5: WhoProfits | O5: =SUMIF($I$2:$I$1000,"*Who Profits*",$H$2:$H$1000) -> 0
H6: =SUMIF($D$2:$D$1000,G6,$E$2:$E$1000) -> 0
H7: =SUMIF($D$2:$D$1000,G7,$E$2:$E$1000) -> 0 | N7: Bank | O7: Value
H8: =SUMIF($D$2:$D$1000,G8,$E$2:$E$1000) -> 0 | N8: Danske Bank | O8: =SUMIF($B$2:$B$1000,"*Danske Bank*",$E$2:$E$1000) -> 0
H9: =SUMIF($D$2:$D$1000,G9,$E$2:$E$1000) -> 0 | N9: Jyske Bank | O9: =SUMIF($B$2:$B$1000,"*Jyske Bank*",$E$2:$E$1000) -> 0
H10: =SUMIF($D$2:$D$1000,G10,$E$2:$E$1000) -> 0 | N10: SEB | O10: =SUMIF($B$2:$B$1000,"*SEB*",$E$2:$E$1000) -> 0
H11: =SUMIF($D$2:$D$1000,G11,$E$2:$E$1000) -> 0
H12: =SUMIF($D$2:$D$1000,G12,$E$2:$E$1000) -> 0 | N12: Total
H13: =SUMIF($D$2:$D$1000,G13,$E$2:$E$1000) -> 0 | N13: =SUM(E2:E1000) -> 0
H14: =SUMIF($D$2:$D$1000,G14,$E$2:$E$1000) -> 0
H15: =SUMIF($D$2:$D$1000,G15,$E$2:$E$1000) -> 0
H16: =SUMIF($D$2:$D$1000,G16,$E$2:$E$1000) -> 0
H17: =SUMIF($D$2:$D$1000,G17,$E$2:$E$1000) -> 0
H18: =SUMIF($D$2:$D$1000,G18,$E$2:$E$1000) -> 0
H19: =SUMIF($D$2:$D$1000,G19,$E$2:$E$1000) -> 0
H20: =SUMIF($D$2:$D$1000,G20,$E$2:$E$1000) -> 0
H21: =SUMIF($D$2:$D$1000,G21,$E$2:$E$1000) -> 0
H22: =SUMIF($D$2:$D$1000,G22,$E$2:$E$1000) -> 0
H23: =SUMIF($D$2:$D$1000,G23,$E$2:$E$1000) -> 0
H24: =SUMIF($D$2:$D$1000,G24,$E$2:$E$1000) -> 0
H25: =SUMIF($D$2:$D$1000,G25,$E$2:$E$1000) -> 0
... H151: =SUMIF($D$2:$D$1000,G151,$E$2:$E$1000) -> 0
